Workbook
Name Column1: 'Base de datos'!$G$73:$G$78
Name ESTADO: Table2[[ESTADO ]]

Sheet Base de datos
A1: N.º | B1: Documento
A2: 2.1. | B2: Carta de autorización y aprobación de planos
A3: 2.2. | B3: Certificado de no objeción
A4: 2.3. | B4: Certificado de no objeción
A5: 2.4. | B5: Certificación de registro de impacto mínimo
A6: 2.5. | B6: Licencia de construcción
A7: 2.6. | B7: Certificación (gestión de costos Y presupuestos)
A8: 2.7.
A9: 2.8.
A10: 2.9.
A11: 2.10.
A12: 2.11.
A13: 2.2.1. | B13: Plano de coordenadas / solar.
A14: 2.2.2. | B14: Plano curvas de nivel.
A15: 2.2.3. | B15: Plano puntos de sondeo.
A16: 2.2.4. | B16: Estudio de suelo.
A17: 2.2.5. | B17: Planta de Charrancha y Ejes.
A18: 2.2.6. | B18: 0
A19: 3.1. | B19: Memoria descriptiva del proyecto:
A20: 3.2. | B20: Memoria de materiales del proyecto:
A21: 3.3. | B21: Especificaciones de equipos sanitarios, eléctricos y de mecánicos:
A22: 3.4. | B22: Listado de materiales:
A23: 3.5. | B23: Dossier de aparatos sanitarios:
A24: 3.6. | B24: Dossier de herrajes:
A25: 3.7. | B25: 0
A26: 3.8. | B26: Localización y ubicación:
A27: 3.9. | B27: Plano de conjunto:
A28: 3.10. | B28: Planta arquitectónica de conjunto (Por niveles):
A29: 3.11. | B29: Plano de paisajismo esquemático:
A30: 3.12. | B30: Plano de paisajismo definitivo:
A31: 3.13. | B31: 0
A32: 3.14. | B32: Plantas dimensionadas (por nivel):
A33: 3.15. | B33: Plantas de pisos (por nivel):
A34: 3.16. | B34: Elevaciones con especificaciones de materiales:
A35: 3.17. | B35: Secciones con especificaciones de materiales:
A36: 3.18. | B36: Ubicación de cuarto para equipos sanitarios:
A37: 3.19. | B37: Ubicación de compresores:
A38: 3.20. | B38: Ubicación en planos del contenedor de basura:
A39: 3.21. | B39: Ubicación en planos del tanque de gas:
A40: 3.22. | B40: Ubicación en planos del área para calentadores:
...

Sheet RESUMEN
A1: 1. Datos generales
A2: Proyecto: | C2: Lagos Las Nasas 09 | D2: Ubicación del proyecto: | F2: Punta Cana Resort & Club
A3: m2 de construcción: | C3: 972.98 m2 | D3: m2 de solar: | F3: 1775.18 m2
A4: Arquitecto Encargado: | C4: Priscilla Lora | D4: Gerente del proyecto: | F4: -
A5: Tipo de proyecto: | C5: Clientes | D5: Propietario: | F5: Melissa Raiti-Knapp & Jon Knapp
A6: Fecha de inicio del proyecto: | C6: - | D6: Fecha de finalización del proyecto: | F6: -
A7: Fecha de inicio recepción de documentación: | C7: 21.11.2025 | D7: Fecha de actualización: | F7: 03.12.2025
A8: 2. Permisologías
A9: N.º | B9: Documento | C9: Institución que emite | D9: Estado | E9: Responsable | F9: Observaciones
A10: 2.1. | B10: =+VLOOKUP(A10,'Base de datos'!$A$2:$B$163,2,FALSE) -> Carta de autorización y aprobación de planos | C10: GPC/ otros | G10: 4
A11: 2.2. | B11: =+VLOOKUP(A11,'Base de datos'!$A$2:$B$163,2,FALSE) -> Certificado de no objeción | C11: Ayuntamiento | G11: =+G10+$H$34 -> 12
A12: 2.3. | B12: =+VLOOKUP(A12,'Base de datos'!$A$2:$B$163,2,FALSE) -> Certificado de no objeción | C12: Ministerio de Turismo | G12: =+G11+$H$34 -> 20
A13: 2.4. | B13: =+VLOOKUP(A13,'Base de datos'!$A$2:$B$163,2,FALSE) -> Certificación de registro de impacto mínimo | C13: Ministerio de Medio Ambiente | G13: =+G12+$H$34 -> 28
A14: 2.5. | B14: =+VLOOKUP(A14,'Base de datos'!$A$2:$B$163,2,FALSE) -> Licencia de construcción | C14: Ministerio de Obras Públicas | G14: =+G13+$H$34 -> 36
A15: 2.6. | B15: =+VLOOKUP(A15,'Base de datos'!$A$2:$B$163,2,FALSE) -> Certificación (gestión de costos Y presupuestos) | C15: Codia | G15: =+G14+$H$34 -> 44
A16: Otros documentos
A17: N.º | B17: Documento | C17: Institución que emite | D17: Estado | E17: Responsable | F17: Observaciones
A18: 2.7. | B18: =+VLOOKUP(A18,'Base de datos'!$A$2:$B$163,2,FALSE) -> 0 | G18: =+G15+$H$34 -> 52
A19: 2.8. | B19: =+VLOOKUP(A19,'Base de datos'!$A$2:$B$163,2,FALSE) -> 0 | G19: =+G18+$H$34 -> 60
A20: 2.9. | B20: =+VLOOKUP(A20,'Base de datos'!$A$2:$B$163,2,FALSE) -> 0 | G20: =+G19+$H$34 -> 68
A21: 2.10. | B21: =+VLOOKUP(A21,'Base de datos'!$A$2:$B$163,2,FALSE) -> 0 | G21: =+G20+$H$34 -> 76
A22: 2.11. | B22: =+VLOOKUP(A22,'Base de datos'!$A$2:$B$163,2,FALSE) -> 0 | G22: =+G21+$H$34 -> 84
A23: Planos topográficos
A24: N.º | B24: Documento | C24: Fecha de recepción | D24: Estado | E24: Responsable | F24: Observaciones
A25: 2.2.1. | B25: =+VLOOKUP(A25,'Base de datos'!$A$2:$B$163,2,FALSE) -> Plano de coordenadas / solar. | C25: 25.11.2025 | D25: COMPLETO | E25: Contructora Dupla
A26: 2.2.2. | B26: =+VLOOKUP(A26,'Base de datos'!$A$2:$B$163,2,FALSE) -> Plano curvas de nivel. | D26: NO APLICA
A27: 2.2.3. | B27: =+VLOOKUP(A27,'Base de datos'!$A$2:$B$163,2,FALSE) -> Plano puntos de sondeo. | C27: 24.11.2025 | D27: COMPLETO | E27: Desangles Abreu | F27: Pagina 48 de estudio de suelo
A28: 2.2.4. | B28: =+VLOOKUP(A28,'Base de datos'!$A$2:$B$163,2,FALSE) -> Estudio de suelo. | C28: 24.11.2025 | D28: COMPLETO | E28: Desangles Abreu
A29: 2.2.5. | B29: =+VLOOKUP(A29,'Base de datos'!$A$2:$B$163,2,FALSE) -> Planta de Charrancha y Ejes. | D29: FALTANTE | E29: Contructora Dupla
A30: 2.2.6. | B30: =+VLOOKUP(A30,'Base de datos'!$A$2:$B$163,2,FALSE) -> 0
A31: 3. Planos arquitectónicos
A32: Memoria descriptiva del proyecto y materiales
A33: N.º | B33: Documento | C33: Fecha de recepción | D33: Estado | E33: Responsable | F33: Observaciones
A34: 3.1. | B34: =+VLOOKUP(A34,'Base de datos'!$A$2:$B$163,2,FALSE) -> Memoria descriptiva del proyecto: | D34: FALTANTE | E34: Desangles Abreu | G34: 4 | H34: 8
A35: 3.2. | B35: =+VLOOKUP(A35,'Base de datos'!$A$2:$B$163,2,FALSE) -> Memoria de materiales del proyecto: | C35: 27.11.2025 | D35: COMPLETO | E35: Desangles Abreu | G35: =+G34+$H$34 -> 12
A36: 3.3. | B36: =+VLOOKUP(A36,'Base de datos'!$A$2:$B$163,2,FALSE) -> Especificaciones de equipos sanitarios, eléctricos y de mecánicos: | C36: 27.11.2025 | D36: COMPLETO | E36: Desangles Abreu | F36: Sugerencias de terminaciones y calidad de equipos | G36: =+G35+$H$34 -> 20
A37: 3.4. | B37: =+VLOOKUP(A37,'Base de datos'!$A$2:$B$163,2,FALSE) -> Listado de materiales: | D37: FALTANTE | E37: Contructora Dupla | G37: =+G36+$H$34 -> 28
A38: 3.5. | B38: =+VLOOKUP(A38,'Base de datos'!$A$2:$B$163,2,FALSE) -> Dossier de aparatos sanitarios: | D38: FALTANTE | E38: Contructora Dupla
A39: 3.6. | B39: =+VLOOKUP(A39,'Base de datos'!$A$2:$B$163,2,FALSE) -> Dossier de herrajes: | D39: FALTANTE | E39: Contructora Dupla | F39: Sugerencias de terminaciones y calidad de herrajes
A40: 3.7. | B40: =+VLOOKUP(A40,'Base de datos'!$A$2:$B$163,2,FALSE) -> 0
...

Sheet ACTA DE AVANCE DE INFORMACIÓN 2
A1: 1. Datos generales
A3: Proyecto: | F3: Fecha de solicitud:
A4: Consecutivo de avance: | F4: Fecha de actualización:
A6: 2. Solicitud de información
A7: N.º | B7: Partida | C7: Información solicitada | D7: Fecha de Incio de Actividad | E7: Duración en ejecución (Días) | F7: ¿Es ruta critica? | G7: Responsable | H7: Fecha de inicio para modificación | I7: Fecha de inicio para modificación
A30: Observaciones:

Sheet ACTA DE AVANCE DE MODIFICACÓN
A1: 1. Datos generales
A3: Proyecto:
A4: N.º de avance:
A6: 2. Modificaciones en planos
A7: N.º | B7: Partida | C7: Información en modificación | D7: Responsable | E7: Fecha de inicio de modificación | F7: Seguimiento de solicitud (Días) | G7: Fecha de entrega
A30: Observaciones:
